Workbook

Sheet Clarks Fork Basin
A1: Age_Ma_Westerhold_2018 | B1: Depth_m_PCB_core | C1: height_above_onset | D1: est_Depth_m_PCB_outcrop | E1: Age_Ma_best_estimate | F1: basis
D2: 2200 | E2: 54 | F2: Biohorizon B (Wa-4/5 boundary, Clyde et al., (2007)
A3: 55.626 | B3: 7.9 | C3: =$B$17-B3 -> 107.45 | D3: =D$17+C3 -> 1613.8 | E3: 55.626 | F3: Correlation from PCB drill core to PCB outcrop, hung on onset PETM CIE, based on drill core age model by Westerhold et al. (2020)
A4: 55.647 | B4: 16.1 | C4: =$B$17-B4 -> 99.25 | D4: =D$17+C4 -> 1605.6 | E4: 55.647 | F4: Correlation from PCB drill core to PCB outcrop, hung on onset PETM CIE, based on drill core age model by Westerhold et al. (2020)
A5: 55.668 | B5: 23.5 | C5: =$B$17-B5 -> 91.85 | D5: =D$17+C5 -> 1598.2 | E5: 55.668 | F5: Correlation from PCB drill core to PCB outcrop, hung on onset PETM CIE, based on drill core age model by Westerhold et al. (2020)
A6: 55.689 | B6: 31.2 | C6: =$B$17-B6 -> 84.15 | D6: =D$17+C6 -> 1590.5 | E6: 55.689 | F6: Correlation from PCB drill core to PCB outcrop, hung on onset PETM CIE, based on drill core age model by Westerhold et al. (2020)
A7: 55.71 | B7: 38.2 | C7: =$B$17-B7 -> 77.15 | D7: =D$17+C7 -> 1583.5 | E7: 55.71 | F7: Correlation from PCB drill core to PCB outcrop, hung on onset PETM CIE, based on drill core age model by Westerhold et al. (2020)
A8: 55.731 | B8: 44.6 | C8: =$B$17-B8 -> 70.75 | D8: =D$17+C8 -> 1577.1 | E8: 55.731 | F8: Correlation from PCB drill core to PCB outcrop, hung on onset PETM CIE, based on drill core age model by Westerhold et al. (2020)
A9: 55.752 | B9: 51 | C9: =$B$17-B9 -> 64.35 | D9: =D$17+C9 -> 1570.7 | E9: 55.752 | F9: Correlation from PCB drill core to PCB outcrop, hung on onset PETM CIE, based on drill core age model by Westerhold et al. (2020)
A10: 55.773 | B10: 58.2 | C10: =$B$17-B10 -> 57.15 | D10: =D$17+C10 -> 1563.5 | E10: 55.773 | F10: Correlation from PCB drill core to PCB outcrop, hung on onset PETM CIE, based on drill core age model by Westerhold et al. (2020)
A11: 55.794 | B11: 65.85 | C11: =$B$17-B11 -> 49.5 | D11: =D$17+C11 -> 1555.85 | E11: 55.794 | F11: Correlation from PCB drill core to PCB outcrop, hung on onset PETM CIE, based on drill core age model by Westerhold et al. (2020)
A12: 55.815 | B12: 74.4 | C12: =$B$17-B12 -> 40.95 | D12: =D$17+C12 -> 1547.3 | E12: 55.815 | F12: Correlation from PCB drill core to PCB outcrop, hung on onset PETM CIE, based on drill core age model by Westerhold et al. (2020)
A13: 55.836 | B13: 82.6 | C13: =$B$17-B13 -> 32.75 | D13: =D$17+C13 -> 1539.1 | E13: 55.836 | F13: Correlation from PCB drill core to PCB outcrop, hung on onset PETM CIE, based on drill core age model by Westerhold et al. (2020)
A14: 55.857 | B14: 91.1 | C14: =$B$17-B14 -> 24.25 | D14: =D$17+C14 -> 1530.6 | E14: 55.857 | F14: Correlation from PCB drill core to PCB outcrop, hung on onset PETM CIE, based on drill core age model by Westerhold et al. (2020)
... A17: 55.92 | B17: 115.35 | C17: =$B$17-B17 -> 0 | D17: =D$17+C17 -> 1506.35 | E17: 55.92 | F17: Correlation from PCB drill core to PCB outcrop, hung on onset PETM CIE, based on drill core age model by Westerhold et al. (2020)
A18: 55.93 | B18: 118.7 | C18: 0 | D18: 1503 | E18: 55.93 | F18: Polecat Bench CIE onset, Westerhold et al. (2020)
A19: 55.94 | B19: 123 | C19: =$B$17-B19 -> -7.65 | D19: =$D$17+C19 -> 1498.7 | E19: 55.94 | F19: Correlation from PCB drill core to PCB outcrop, hung on onset PETM CIE, based on drill core age model by Westerhold et al. (2020) | K19: General precision of K-Pg meter level framework: +/- 5m (Gingerich 2010)
A20: 55.961 | B20: 130 | C20: =$B$17-B20 -> -14.65 | D20: =$D$17+C20 -> 1491.7 | E20: 55.961 | F20: Correlation from PCB drill core to PCB outcrop, hung on onset PETM CIE, based on drill core age model by Westerhold et al. (2020)
A21: 55.982 | B21: 139.3 | C21: =$B$17-B21 -> -23.95 | D21: =$D$17+C21 -> 1482.4 | E21: 55.982 | F21: Correlation from PCB drill core to PCB outcrop, hung on onset PETM CIE, based on drill core age model by Westerhold et al. (2020)
A22: 56.003 | B22: 146.5 | C22: =$B$17-B22 -> -31.15 | D22: =$D$17+C22 -> 1475.2 | E22: 56.003 | F22: Correlation from PCB drill core to PCB outcrop, hung on onset PETM CIE, based on drill core age model by Westerhold et al. (2020)
A23: 56.024 | B23: 155 | C23: =$B$17-B23 -> -39.65 | D23: =$D$17+C23 -> 1466.7 | E23: 56.024 | F23: Correlation from PCB drill core to PCB outcrop, hung on onset PETM CIE, based on drill core age model by Westerhold et al. (2020)
A24: 56.045 | B24: 164 | C24: =$B$17-B24 -> -48.65 | D24: =$D$17+C24 -> 1457.7 | E24: 56.045 | F24: Correlation from PCB drill core to PCB outcrop, hung on onset PETM CIE, based on drill core age model by Westerhold et al. (2020)
A25: 56.066 | B25: 171.2 | C25: =$B$17-B25 -> -55.85 | D25: =$D$17+C25 -> 1450.5 | E25: 56.066 | F25: Correlation from PCB drill core to PCB outcrop, hung on onset PETM CIE, based on drill core age model by Westerhold et al. (2020)
A26: 56.087 | B26: 181.7 | C26: =$B$17-B26 -> -66.35 | D26: =$D$17+C26 -> 1440 | E26: 56.087 | F26: Correlation from PCB drill core to PCB outcrop, hung on onset PETM CIE, based on drill core age model by Westerhold et al. (2020)
A27: 56.108 | B27: 189.5 | C27: =$B$17-B27 -> -74.15 | D27: =$D$17+C27 -> 1432.2 | E27: 56.108 | F27: Correlation from PCB drill core to PCB outcrop, hung on onset PETM CIE, based on drill core age model by Westerhold et al. (2020)
A28: 56.171 | B28: 208.7 | C28: =$B$17-B28 -> -93.35 | D28: =$D$17+C28 -> 1413 | E28: 56.171 | F28: Correlation from PCB drill core to PCB outcrop, hung on onset PETM CIE, based on drill core age model by Westerhold et al. (2020)
A29: 56.234 | B29: 228.6 | C29: =$B$17-B29 -> -113.25 | D29: =$D$17+C29 -> 1393.1 | E29: 56.234 | F29: Correlation from PCB drill core to PCB outcrop, hung on onset PETM CIE, based on drill core age model by Westerhold et al. (2020)
A30: 56.255 | B30: 235.7 | C30: =$B$17-B30 -> -120.35 | D30: =$D$17+C30 -> 1386 | E30: 56.255 | F30: Correlation from PCB drill core to PCB outcrop, hung on onset PETM CIE, based on drill core age model by Westerhold et al. (2020)
A31: 56.276 | B31: 243.5 | C31: =$B$17-B31 -> -128.15 | D31: =$D$17+C31 -> 1378.2 | E31: 56.276 | F31: Correlation from PCB drill core to PCB outcrop, hung on onset PETM CIE, based on drill core age model by Westerhold et al. (2020)
A32: 56.297 | B32: 251.6 | C32: =$B$17-B32 -> -136.25 | D32: =$D$17+C32 -> 1370.1 | E32: 56.297 | F32: Correlation from PCB drill core to PCB outcrop, hung on onset PETM CIE, based on drill core age model by Westerhold et al. (2020)
D33: 787 | E33: 57.656 | F33: base C25n, SE PCB, datum: Secord et al. (2006), age: GTS 2020
D34: 470 | E34: 58.959 | F34: base C25r, SE PCB, datum: Secord et al. (2006), age: GTS 2020
D35: 370 | E35: 59.237 | F35: base C26n, SE PCB, datum: Secord et al. (2006), age: GTS 2020
D36: 331 | E36: 59.3 | F36: Belt Ash sanadine Ar36/Ar40 dating, SE PCB, Secord et al. (2006). Age reported as 59.0 +/- 0.3 Ma. Given | N36: Red: AI estimated
D37: 83 | E37: 62.278 | F37: base C26r, SE PCB, datum: Secord et al. (2006), age: GTS 2020 | N37: Green: MLA validated
L39: Marker | M39: Approx. Age (Ma) | O39: Marker | P39: Strat level (m)
L40: Top Red B | M40: 55.778 | O40: Top Red B | P40: 1553.5
L41: Top Red A | M41: 55.797 | O41: Top Red A | P41: 1549.5
L42: Purple-4 | M42: 55.817 | O42: Purple-4 | P42: 1542
L43: Purple-3 | M43: 55.84 | O43: Purple-3 | P43: 1536.5
...

Sheet McCullough Peaks
A1: Event | B1: Clyde1994_m_level | C1: Koch2003_m_above_Kpg | D1: Age (Ma) | E1: basis
A2: Base of C24n.1r | B2: 1390 | C2: 2515 | D2: 53.02 | E2: Clyde et al. (1994), GTS2020
A3: Base of C24n.2n | B3: 1340 | C3: 2460 | D3: 53.12 | E3: Clyde et al. (1994), GTS2020
A4: Base of C24n.2r | B4: 1300 | C4: 2420 | D4: 53.25 | E4: Clyde et al. (1994), GTS2020
A5: Base of C24n.3n | B5: 950 | C5: 2100 | D5: 53.9 | E5: Clyde et al. (1994), GTS2020
A6: Base of Wa 0 | B6: 0 | C6: 1195 | D6: 55.9 | E6: base of PETM CIE, Westerhold et al. (2018)

Sheet Southern Bighorn Basin
A1: Event | B1: Clyde2007_level_m | C1: Koch2003_level_m | D1: Age (Ma) | E1: Age 95% CI | F1: basis
A2: Top of C24n.2n | D2: 53.02 | F2: Clyde et al. (2007), GTS2020
A3: Base of C24n.2n | D3: 53.12 | F3: Clyde et al. (2007), GTS2020
A4: Base of C24n.3n | D4: 53.9 | F4: Clyde et al. (2007), GTS2020
A5: Base of Wa 0 | D5: 55.9 | F5: base of PETM CIE, Westerhold et al. (2018)
A6: Base of C24r | D6: 57.101 | F6: Clyde et al. (2007), GTS2020
A7: Base of C25n | D7: 57.656 | F7: Clyde et al. (2007), GTS2020
A8: Base of C26r | D8: 62.278 | F8: Clyde et al. (2007), GTS2020

Sheet Pg GTS2020 Magnetochrons
A1: Magnetochron (Base) | B1: GTS2020 Age (Ma) | C1: Primary calibration reference (GTS2020)
A2: C12n | B2: 30.977 | C2: Westerhold et al. (2014) – PEAT
A3: C12r | B3: 33.214 | C3: —
A4: C13n | B4: 33.726 | C4: —
A5: C13r | B5: 35.102 | C5: Westerhold et al. (2014) – PEAT (used in GTS2016)
A6: C15n | B6: 35.336 | C6: —
A7: C15r | B7: 35.58 | C7: —
A8: C16n.1n | B8: 35.718 | C8: —
A9: C16n.1r | B9: 35.774 | C9: —
A10: C16n.2n | B10: 36.351 | C10: —
A11: C16r | B11: 36.573 | C11: —
A12: C17n.1n | B12: 37.385 | C12: —
A13: C17n.1r | B13: 37.53 | C13: —
... A49: K/Pg | B49: 66.001 | C49: —

Sheet CFB_standardized
A1: source_sheet | B1: source_row | C1: event | D1: composite_section | E1: strat_height_m | F1: strat_height_datum | G1: alternate_strat_height_m | H1: alternate_strat_datum | I1: relative_height_m | J1: relative_height_datum | K1: age_Ma | L1: age_source | M1: strat_source | N1: control_type | O1: use_as_age_prior | P1: relationship_status | Q1: basis_comments
A2: Clarks Fork Basin | B2: 2 | C2: Biohorizon B (Wa-4/5 boundary) | D2: CFB | E2: 2200 | F2: m above K-Pg; PCB/CFB outcrop framework | K2: 54 | L2: Entered source age | M2: Clyde et al. (2007) | N2: biohorizon | O2: TRUE | P2: entered relationship preserved | Q2: Biohorizon B (Wa-4/5 boundary, Clyde et al., (2007)
A3: Clarks Fork Basin | B3: 3 | C3: PCB core age-depth point | D3: CFB | E3: 1613.8 | F3: m above K-Pg; PCB/CFB outcrop framework | G3: 7.9 | H3: PCB drill-core depth (m) | I3: 107.45 | J3: m relative to PETM CIE onset | K3: 55.626 | L3: Westerhold et al. chronology | M3: PCB core-outcrop CIE correlation | N3: age-depth correlation | O3: TRUE | P3: entered relationship preserved | Q3: Correlation from PCB drill core to PCB outcrop, hung on onset PETM CIE, based on drill core age model by Westerhold et al. (2020)
A4: Clarks Fork Basin | B4: 4 | C4: PCB core age-depth point | D4: CFB | E4: 1605.6 | F4: m above K-Pg; PCB/CFB outcrop framework | G4: 16.1 | H4: PCB drill-core depth (m) | I4: 99.25 | J4: m relative to PETM CIE onset | K4: 55.647 | L4: Westerhold et al. chronology | M4: PCB core-outcrop CIE correlation | N4: age-depth correlation | O4: TRUE | P4: entered relationship preserved | Q4: Correlation from PCB drill core to PCB outcrop, hung on onset PETM CIE, based on drill core age model by Westerhold et al. (2020)
A5: Clarks Fork Basin | B5: 5 | C5: PCB core age-depth point | D5: CFB | E5: 1598.2 | F5: m above K-Pg; PCB/CFB outcrop framework | G5: 23.5 | H5: PCB drill-core depth (m) | I5: 91.85 | J5: m relative to PETM CIE onset | K5: 55.668 | L5: Westerhold et al. chronology | M5: PCB core-outcrop CIE correlation | N5: age-depth correlation | O5: TRUE | P5: entered relationship preserved | Q5: Correlation from PCB drill core to PCB outcrop, hung on onset PETM CIE, based on drill core age model by Westerhold et al. (2020)
A6: Clarks Fork Basin | B6: 6 | C6: PCB core age-depth point | D6: CFB | E6: 1590.5 | F6: m above K-Pg; PCB/CFB outcrop framework | G6: 31.2 | H6: PCB drill-core depth (m) | I6: 84.15 | J6: m relative to PETM CIE onset | K6: 55.689 | L6: Westerhold et al. chronology | M6: PCB core-outcrop CIE correlation | N6: age-depth correlation | O6: TRUE | P6: entered relationship preserved | Q6: Correlation from PCB drill core to PCB outcrop, hung on onset PETM CIE, based on drill core age model by Westerhold et al. (2020)
A7: Clarks Fork Basin | B7: 7 | C7: PCB core age-depth point | D7: CFB | E7: 1583.5 | F7: m above K-Pg; PCB/CFB outcrop framework | G7: 38.2 | H7: PCB drill-core depth (m) | I7: 77.15 | J7: m relative to PETM CIE onset | K7: 55.71 | L7: Westerhold et al. chronology | M7: PCB core-outcrop CIE correlation | N7: age-depth correlation | O7: TRUE | P7: entered relationship preserved | Q7: Correlation from PCB drill core to PCB outcrop, hung on onset PETM CIE, based on drill core age model by Westerhold et al. (2020)
A8: Clarks Fork Basin | B8: 8 | C8: PCB core age-depth point | D8: CFB | E8: 1577.1 | F8: m above K-Pg; PCB/CFB outcrop framework | G8: 44.6 | H8: PCB drill-core depth (m) | I8: 70.75 | J8: m relative to PETM CIE onset | K8: 55.731 | L8: Westerhold et al. chronology | M8: PCB core-outcrop CIE correlation | N8: age-depth correlation | O8: TRUE | P8: entered relationship preserved | Q8: Correlation from PCB drill core to PCB outcrop, hung on onset PETM CIE, based on drill core age model by Westerhold et al. (2020)
A9: Clarks Fork Basin | B9: 9 | C9: PCB core age-depth point | D9: CFB | E9: 1570.7 | F9: m above K-Pg; PCB/CFB outcrop framework | G9: 51 | H9: PCB drill-core depth (m) | I9: 64.35 | J9: m relative to PETM CIE onset | K9: 55.752 | L9: Westerhold et al. chronology | M9: PCB core-outcrop CIE correlation | N9: age-depth correlation | O9: TRUE | P9: entered relationship preserved | Q9: Correlation from PCB drill core to PCB outcrop, hung on onset PETM CIE, based on drill core age model by Westerhold et al. (2020)
A10: Clarks Fork Basin | B10: 10 | C10: PCB core age-depth point | D10: CFB | E10: 1563.5 | F10: m above K-Pg; PCB/CFB outcrop framework | G10: 58.2 | H10: PCB drill-core depth (m) | I10: 57.15 | J10: m relative to PETM CIE onset | K10: 55.773 | L10: Westerhold et al. chronology | M10: PCB core-outcrop CIE correlation | N10: age-depth correlation | O10: TRUE | P10: entered relationship preserved | Q10: Correlation from PCB drill core to PCB outcrop, hung on onset PETM CIE, based on drill core age model by Westerhold et al. (2020)
A11: Clarks Fork Basin | B11: 11 | C11: PCB core age-depth point | D11: CFB | E11: 1555.85 | F11: m above K-Pg; PCB/CFB outcrop framework | G11: 65.85 | H11: PCB drill-core depth (m) | I11: 49.5 | J11: m relative to PETM CIE onset | K11: 55.794 | L11: Westerhold et al. chronology | M11: PCB core-outcrop CIE correlation | N11: age-depth correlation | O11: TRUE | P11: entered relationship preserved | Q11: Correlation from PCB drill core to PCB outcrop, hung on onset PETM CIE, based on drill core age model by Westerhold et al. (2020)
A12: Clarks Fork Basin | B12: 12 | C12: PCB core age-depth point | D12: CFB | E12: 1547.3 | F12: m above K-Pg; PCB/CFB outcrop framework | G12: 74.4 | H12: PCB drill-core depth (m) | I12: 40.95 | J12: m relative to PETM CIE onset | K12: 55.815 | L12: Westerhold et al. chronology | M12: PCB core-outcrop CIE correlation | N12: age-depth correlation | O12: TRUE | P12: entered relationship preserved | Q12: Correlation from PCB drill core to PCB outcrop, hung on onset PETM CIE, based on drill core age model by Westerhold et al. (2020)
A13: Clarks Fork Basin | B13: 13 | C13: PCB core age-depth point | D13: CFB | E13: 1539.1 | F13: m above K-Pg; PCB/CFB outcrop framework | G13: 82.6 | H13: PCB drill-core depth (m) | I13: 32.75 | J13: m relative to PETM CIE onset | K13: 55.836 | L13: Westerhold et al. chronology | M13: PCB core-outcrop CIE correlation | N13: age-depth correlation | O13: TRUE | P13: entered relationship preserved | Q13: Correlation from PCB drill core to PCB outcrop, hung on onset PETM CIE, based on drill core age model by Westerhold et al. (2020)
A14: Clarks Fork Basin | B14: 14 | C14: PCB core age-depth point | D14: CFB | E14: 1530.6 | F14: m above K-Pg; PCB/CFB outcrop framework | G14: 91.1 | H14: PCB drill-core depth (m) | I14: 24.25 | J14: m relative to PETM CIE onset | K14: 55.857 | L14: Westerhold et al. chronology | M14: PCB core-outcrop CIE correlation | N14: age-depth correlation | O14: TRUE | P14: entered relationship preserved | Q14: Correlation from PCB drill core to PCB outcrop, hung on onset PETM CIE, based on drill core age model by Westerhold et al. (2020)
... A32: Clarks Fork Basin | B32: 32 | C32: PCB core age-depth point | D32: CFB | E32: 1370.1 | F32: m above K-Pg; PCB/CFB outcrop framework | G32: 251.6 | H32: PCB drill-core depth (m) | I32: -136.25 | J32: m relative to PETM CIE onset | K32: 56.297 | L32: Westerhold et al. chronology | M32: PCB core-outcrop CIE correlation | N32: age-depth correlation | O32: TRUE | P32: entered relationship preserved | Q32: Correlation from PCB drill core to PCB outcrop, hung on onset PETM CIE, based on drill core age model by Westerhold et al. (2020)
A33: Clarks Fork Basin | B33: 33 | C33: Base C25n | D33: CFB | E33: 787 | F33: m above K-Pg; PCB/CFB outcrop framework | K33: ='Pg GTS2020 Magnetochrons'!B40 -> 57.656 | L33: GTS2020 magnetochron sheet | M33: Secord et al. (2006) | N33: magnetochron | O33: TRUE | P33: entered relationship preserved | Q33: base C25n, SE PCB, datum: Secord et al. (2006), age: GTS 2020
A34: Clarks Fork Basin | B34: 34 | C34: Base C25r | D34: CFB | E34: 470 | F34: m above K-Pg; PCB/CFB outcrop framework | K34: ='Pg GTS2020 Magnetochrons'!B41 -> 58.959 | L34: GTS2020 magnetochron sheet | M34: Secord et al. (2006) | N34: magnetochron | O34: TRUE | P34: entered relationship preserved | Q34: base C25r, SE PCB, datum: Secord et al. (2006), age: GTS 2020
A35: Clarks Fork Basin | B35: 35 | C35: Base C26n | D35: CFB | E35: 370 | F35: m above K-Pg; PCB/CFB outcrop framework | K35: ='Pg GTS2020 Magnetochrons'!B42 -> 59.237 | L35: GTS2020 magnetochron sheet | M35: Secord et al. (2006) | N35: magnetochron | O35: TRUE | P35: entered relationship preserved | Q35: base C26n, SE PCB, datum: Secord et al. (2006), age: GTS 2020
A36: Clarks Fork Basin | B36: 36 | C36: Belt Ash | D36: CFB | E36: 331 | F36: m above K-Pg; PCB/CFB outcrop framework | K36: 59.3 | L36: Secord et al. (2006) | M36: Secord et al. (2006) | N36: radiometric | O36: TRUE | P36: entered relationship preserved | Q36: Belt Ash sanadine Ar36/Ar40 dating, SE PCB, Secord et al. (2006). Age reported as 59.0 +/- 0.3 Ma. Given
A37: Clarks Fork Basin | B37: 37 | C37: Base C26r | D37: CFB | E37: 83 | F37: m above K-Pg; PCB/CFB outcrop framework | K37: ='Pg GTS2020 Magnetochrons'!B43 -> 62.278 | L37: GTS2020 magnetochron sheet | M37: Secord et al. (2006) | N37: magnetochron | O37: TRUE | P37: entered relationship preserved | Q37: base C26r, SE PCB, datum: Secord et al. (2006), age: GTS 2020

Sheet MCP_standardized
A1: source_sheet | B1: source_row | C1: event | D1: composite_section | E1: strat_height_m | F1: strat_height_datum | G1: alternate_strat_height_m | H1: alternate_strat_datum | I1: relative_height_m | J1: relative_height_datum | K1: age_Ma | L1: age_source | M1: strat_source | N1: control_type | O1: use_as_age_prior | P1: relationship_status | Q1: basis_comments
A2: McCullough Peaks | B2: 2 | C2: Base C24n.1r | D2: MCP | E2: 2515 | F2: m above K-Pg; Koch et al. (2003) MCP framework | G2: 1390 | H2: Clyde et al. (1994) MCP local level (m) | K2: ='Pg GTS2020 Magnetochrons'!B35 -> 53.02 | L2: GTS2020 magnetochron sheet | M2: Clyde et al. (1994) correlated to Koch et al. (2003) | N2: magnetochron | O2: TRUE | P2: entered relationship preserved | Q2: Clyde et al. (1994), GTS2020
A3: McCullough Peaks | B3: 3 | C3: Base C24n.2n | D3: MCP | E3: 2460 | F3: m above K-Pg; Koch et al. (2003) MCP framework | G3: 1340 | H3: Clyde et al. (1994) MCP local level (m) | K3: ='Pg GTS2020 Magnetochrons'!B36 -> 53.12 | L3: GTS2020 magnetochron sheet | M3: Clyde et al. (1994) correlated to Koch et al. (2003) | N3: magnetochron | O3: TRUE | P3: entered relationship preserved | Q3: Clyde et al. (1994), GTS2020
A4: McCullough Peaks | B4: 4 | C4: Base C24n.2r | D4: MCP | E4: 2420 | F4: m above K-Pg; Koch et al. (2003) MCP framework | G4: 1300 | H4: Clyde et al. (1994) MCP local level (m) | K4: ='Pg GTS2020 Magnetochrons'!B37 -> 53.25 | L4: GTS2020 magnetochron sheet | M4: Clyde et al. (1994) correlated to Koch et al. (2003) | N4: magnetochron | O4: TRUE | P4: entered relationship preserved | Q4: Clyde et al. (1994), GTS2020
A5: McCullough Peaks | B5: 5 | C5: Base C24n.3n | D5: MCP | E5: 2100 | F5: m above K-Pg; Koch et al. (2003) MCP framework | G5: 950 | H5: Clyde et al. (1994) MCP local level (m) | K5: ='Pg GTS2020 Magnetochrons'!B38 -> 53.9 | L5: GTS2020 magnetochron sheet | M5: Clyde et al. (1994) correlated to Koch et al. (2003) | N5: magnetochron | O5: TRUE | P5: entered relationship preserved | Q5: Clyde et al. (1994), GTS2020
A6: McCullough Peaks | B6: 6 | C6: Base Wa0 | D6: MCP | E6: 1195 | F6: m above K-Pg; Koch et al. (2003) MCP framework | G6: 0 | H6: Clyde et al. (1994) MCP local level (m) | K6: 55.9 | L6: Westerhold PETM CIE chronology | M6: Clyde et al. (1994) correlated to Koch et al. (2003) | N6: CIE | O6: TRUE | P6: entered relationship preserved | Q6: base of PETM CIE, Westerhold et al. (2018)

Sheet SBHB_standardized
A1: source_sheet | B1: source_row | C1: event | D1: composite_section | E1: strat_height_m | F1: strat_height_datum | G1: alternate_strat_height_m | H1: alternate_strat_datum | I1: relative_height_m | J1: relative_height_datum | K1: age_Ma | L1: age_source | M1: strat_source | N1: control_type | O1: use_as_age_prior | P1: relationship_status | Q1: basis_comments
A2: Southern Bighorn Basin | B2: 2 | C2: Base C24n.1r | D2: SBHB | F2: Koch et al. (2003) SBHB composite level (m; datum as entered) | H2: Clyde et al. (2007) level (m; native framework) | K2: ='Pg GTS2020 Magnetochrons'!B35 -> 53.02 | L2: GTS2020 magnetochron sheet | M2: Entered source relationship | N2: magnetochron | O2: FALSE | P2: age entered; stratigraphic level unresolved | Q2: Clyde et al. (2007), GTS2020 Source label 'Top of C24n.2n' standardized to equivalent boundary name 'Base C24n.1r'.
A3: Southern Bighorn Basin | B3: 3 | C3: Base C24n.2n | D3: SBHB | F3: Koch et al. (2003) SBHB composite level (m; datum as entered) | H3: Clyde et al. (2007) level (m; native framework) | K3: ='Pg GTS2020 Magnetochrons'!B36 -> 53.12 | L3: GTS2020 magnetochron sheet | M3: Entered source relationship | N3: magnetochron | O3: FALSE | P3: age entered; stratigraphic level unresolved | Q3: Clyde et al. (2007), GTS2020
A4: Southern Bighorn Basin | B4: 4 | C4: Base C24n.3n | D4: SBHB | F4: Koch et al. (2003) SBHB composite level (m; datum as entered) | H4: Clyde et al. (2007) level (m; native framework) | K4: ='Pg GTS2020 Magnetochrons'!B38 -> 53.9 | L4: GTS2020 magnetochron sheet | M4: Entered source relationship | N4: magnetochron | O4: FALSE | P4: age entered; stratigraphic level unresolved | Q4: Clyde et al. (2007), GTS2020
A5: Southern Bighorn Basin | B5: 5 | C5: Base Wa0 | D5: SBHB | E5: 0 | F5: Koch et al. (2003) SBHB composite level (m; datum as entered) | H5: Clyde et al. (2007) level (m; native framework) | K5: 55.9 | L5: Westerhold PETM CIE chronology | M5: Entered source relationship | N5: CIE | O5: FALSE | P5: age entered; stratigraphic level unresolved | Q5: base of PETM CIE, Westerhold et al. (2018)
A6: Southern Bighorn Basin | B6: 6 | C6: Base C24r | D6: SBHB | F6: Koch et al. (2003) SBHB composite level (m; datum as entered) | H6: Clyde et al. (2007) level (m; native framework) | K6: ='Pg GTS2020 Magnetochrons'!B39 -> 57.101 | L6: GTS2020 magnetochron sheet | M6: Entered source relationship | N6: magnetochron | O6: FALSE | P6: age entered; stratigraphic level unresolved | Q6: Clyde et al. (2007), GTS2020
A7: Southern Bighorn Basin | B7: 7 | C7: Base C25n | D7: SBHB | F7: Koch et al. (2003) SBHB composite level (m; datum as entered) | H7: Clyde et al. (2007) level (m; native framework) | K7: ='Pg GTS2020 Magnetochrons'!B40 -> 57.656 | L7: GTS2020 magnetochron sheet | M7: Entered source relationship | N7: magnetochron | O7: FALSE | P7: age entered; stratigraphic level unresolved | Q7: Clyde et al. (2007), GTS2020
A8: Southern Bighorn Basin | B8: 8 | C8: Base C26r | D8: SBHB | F8: Koch et al. (2003) SBHB composite level (m; datum as entered) | H8: Clyde et al. (2007) level (m; native framework) | K8: ='Pg GTS2020 Magnetochrons'!B43 -> 62.278 | L8: GTS2020 magnetochron sheet | M8: Entered source relationship | N8: magnetochron | O8: FALSE | P8: age entered; stratigraphic level unresolved | Q8: Clyde et al. (2007), GTS2020

Sheet GTS2020_standardized
A1: source_sheet | B1: source_row | C1: magnetochron_base | D1: age_Ma | E1: primary_calibration_reference | F1: timescale
A2: Pg GTS2020 Magnetochrons | B2: 2 | C2: C12n | D2: 30.977 | E2: Westerhold et al. (2014) – PEAT | F2: GTS2020
A3: Pg GTS2020 Magnetochrons | B3: 3 | C3: C12r | D3: 33.214 | E3: — | F3: GTS2020
A4: Pg GTS2020 Magnetochrons | B4: 4 | C4: C13n | D4: 33.726 | E4: — | F4: GTS2020
A5: Pg GTS2020 Magnetochrons | B5: 5 | C5: C13r | D5: 35.102 | E5: Westerhold et al. (2014) – PEAT (used in GTS2016) | F5: GTS2020
A6: Pg GTS2020 Magnetochrons | B6: 6 | C6: C15n | D6: 35.336 | E6: — | F6: GTS2020
A7: Pg GTS2020 Magnetochrons | B7: 7 | C7: C15r | D7: 35.58 | E7: — | F7: GTS2020
A8: Pg GTS2020 Magnetochrons | B8: 8 | C8: C16n.1n | D8: 35.718 | E8: — | F8: GTS2020
A9: Pg GTS2020 Magnetochrons | B9: 9 | C9: C16n.1r | D9: 35.774 | E9: — | F9: GTS2020
A10: Pg GTS2020 Magnetochrons | B10: 10 | C10: C16n.2n | D10: 36.351 | E10: — | F10: GTS2020
A11: Pg GTS2020 Magnetochrons | B11: 11 | C11: C16r | D11: 36.573 | E11: — | F11: GTS2020
A12: Pg GTS2020 Magnetochrons | B12: 12 | C12: C17n.1n | D12: 37.385 | E12: — | F12: GTS2020
A13: Pg GTS2020 Magnetochrons | B13: 13 | C13: C17n.1r | D13: 37.53 | E13: — | F13: GTS2020
... A49: Pg GTS2020 Magnetochrons | B49: 49 | C49: K/Pg | D49: 66.001 | E49: — | F49: GTS2020

Sheet README_standardized
A1: Standardized age-calibration tables
A2: Purpose | B2: Machine-readable copies of the locality age-prior tables. All original worksheets are preserved unchanged.
A3: Non-destructive rule | B3: No existing stratigraphic height or age relationship was modified. Blank stratigraphic positions remain blank; no inferred SBHB meter levels were inserted.
A4: Age linkage | B4: Where an event has an exact equivalent in 'Pg GTS2020 Magnetochrons', age_Ma is a formula pointing to that reference sheet. Non-magnetochron ages retain the entered locality-sheet value.
A5: Boundary naming | B5: 'Top of C24n.2n' is standardized as the equivalent boundary 'Base C24n.1r'; the source wording is retained in basis_comments.
A6: Primary stratigraphy | B6: CFB uses est_Depth_m_PCB_outcrop. MCP uses Koch2003_m_above_Kpg. SBHB uses Koch2003_level_m when present. Alternate published meter frameworks are retained separately.
A7: Source traceability | B7: source_sheet and source_row identify the exact original record. basis_comments preserves the original basis text and records any label-only standardization.
A8: use_as_age_prior | B8: TRUE only where the standardized primary strat_height_m and age_Ma are both populated. Unresolved SBHB rows remain documented but are FALSE so they cannot be used accidentally as interpolation priors.
A9: Recommended R filter | B9: filter(use_as_age_prior, !is.na(strat_height_m), !is.na(age_Ma))
A10: Worksheet | B10: Description
A11: CFB_standardized | B11: Clean copy of Clarks Fork Basin/PCB relationships, including core-to-outcrop fields.
A12: MCP_standardized | B12: Clean copy of McCullough Peaks relationships, with Koch 2003 primary and Clyde 1994 alternate heights.
A13: SBHB_standardized | B13: Clean copy of Southern Bighorn Basin entries. Existing unresolved meter levels remain blank.
A14: GTS2020_standardized | B14: Clean reference copy of the magnetochron age table.
